Workbook

Sheet ANA SAYFA
C11: 2025-2026 | F11: XXXX A.Ş.
C12: OCAK-TEMMUZ
C15: KARŞILAŞTIRMALI
C16: FİNANSAL ANALİZ RAPORU
D19: GELİR TABLOSU
D20: VERGİ HESABI
D21: BİLANÇO
D22: BİLANÇO ANALİZİ
D23: ORAN ANALİZİ
D24: EBİTDA
D25: BORCA BATIKLIK
D26: KİK ORANLARI

Sheet GELİR TABLOSU
A2: ANASAYFA | G2: SYF.1
A3: ='ANA SAYFA'!F11
A4: KARŞILAŞTIRMALI AYRINTILI GELİR TABLOSU
A6: H.Kodu | C6: 45869 | D6: Dikey % | E6: 46234 | F6: Dikey % | G6: Yatay %
B7: A- BRÜT SATIŞLAR | C7: =SUM(C9:C11) | D7: =C7/C19*100 | E7: =SUM(E9:E11) | F7: =E7/E19*100 | G7: =(E7-C7)/C7
A9: 600 | B9: 1- Yurtiçi Satışlar | C9: 15522000 | E9: 15492000 | G9: =(E9-C9)/C9
A10: 601 | B10: 2- Yurtdışı Satışlar | C10: 1800000 | E10: 1800000 | G10: =(E10-C10)/C10
A11: 602 | B11: 3- Diğer Gelirler
B13: B- SATIŞ İNDİRİMLERİ (-) | C13: =SUM(C15:C17) | D13: =C13/C19*100 | E13: =SUM(E15:E17) | F13: =E13/E19*100 | G13: =(E13-C13)/C13
A15: 610 | B15: 1- Satıştan İadeler (-) | C15: 220000 | E15: 220000 | G15: =(E15-C15)/C15
A16: 611 | B16: 2- Satış İskontoları (-) | C16: 180000 | E16: 180000
A17: 612 | B17: 3- Diğer İndirimler (-)
B19: C- NET SATIŞLAR | C19: =SUM(C7-C13) | D19: =C19/C19*100 | E19: =SUM(E7-E13) | F19: =E19/E19*100 | G19: =(E19-C19)/C19 | I19: =E19/12
B20: D- SATIŞLARIN MALİYETİ | C20: =SUM(C22:C25) | D20: =C20/C19*100 | E20: =SUM(E22:E24) | F20: =E20/E19*100 | G20: =(E20-C20)/C20
A22: 620 | B22: 1- Satılan Mamuller Maliyeti (-) | C22: 6050000 | E22: 4450000 | G22: =(E22-C22)/C22
A23: 621 | B23: 2- Satılan Ticari Malların Maliyeti (-) | C23: 7300000
A24: 622 | B24: 3- Satılan Hizmet Maliyeti (-)
A25: 623 | B25: 4- Diğer Satışların Maliyeti(-)
B27: BRÜT SATIŞ KARI VEYA ZARARI | C27: =SUM(C19-C20) | D27: =C27/C19*100 | E27: =SUM(E19-E20) | F27: =E27/E19*100 | G27: =(E27-C27)/C27
B29: E- FAALİYET GİDERLERİ (-) | C29: =SUM(C31:C33) | D29: =C29/C19*100 | E29: =SUM(E31:E33) | F29: =E29/E19*100 | G29: =(E29-C29)/C29
A31: 630 | B31: 1- Araştırma Geliştirme Giderleri (-) | E31: 320000 | G31: =(E31-C31)/C31
A32: 631 | B32: 2- Pazarlama,Satış Dağıtım Giderleri (-) | C32: 850000 | E32: 850000 | G32: =(E32-C32)/C32
A33: 632 | B33: 3- Genel Yönetim Giderleri (-) | C33: 1450000 | E33: 1450000 | G33: =(E33-C33)/C33
B35: FAALİYET KARI VEYA ZARARI | C35: =SUM(C27-C29) | D35: =C35/C19*100 | E35: =SUM(E27-E29) | F35: =E35/E19*100 | G35: =(E35-C35)/C35
C36: =C39+C40+C41+C42+C43+C44+C45+C48+C49
B37: F- DİĞER FAALİYETLERDEN OLAĞAN GELİR VEYA KARLAR | D37: =C36/C19*100 | E37: =E39+E40+E41+E42+E43+E44+E45+E48+E49 | F37: =E37/E19*100 | G37: =(E37-C36)/C36
A39: 640 | B39: 1- İştiraklerden Temettü Gelirleri
A40: 641 | B40: 2- Bağlı Ortaklıklardan Temettü Gelirleir
A41: 642 | B41: 3- Faiz Gelirleri | C41: 95000 | E41: 95000 | G41: =(E41-C41)/C41
A42: 643 | B42: 4- Komisyon Gelirleri
A43: 644 | B43: 5- Konusu Kalmayan Karşılıklar
A44: 645 | B44: 6- Menkul Kıymet Satış Karları
A45: 646 | B45: 7- Kambiyo Karları | C45: 240000 | E45: 240000 | G45: =(E45-C45)/C45
B46: 7-a- Yabancı Kaynaklara Ait Kambiyo Karları
B47: 7-b- Diğer Kambiyo Karları
A48: 647 | B48: 8- Reeskont Faiz Gelirleri
A49: 649 | B49: 9- Diğer Olağan Gelir ve Karlar
B51: G- DİĞER FAALİYETLERDEN GİDER VE ZARARLAR (-) | C51: =C53+C54+C55+C56+C59+C60 | D51: =C51/C19*100 | E51: =E53+E54+E56+E59+E60 | F51: =E51/E19*100 | G51: =(E51-C51)/C51
A53: 653 | B53: 1- Komisyon Giderleri | C53: 60000 | E53: 60000
A54: 654 | B54: 2- Karşılık Giderleri
...

Sheet VERGİ HESABI
A1: ANASAYFA | D1: SYF.2 | E1: SYF.2
B3: VERGİ HESABI | C3: ='GELİR TABLOSU'!C6 | D3: ='GELİR TABLOSU'!E6 | E3: ASGARİ KURUMLAR HESAPLAMASI
B5: =IF(C5=0,"TİCARİ BİLANÇO KARI/ZARARI",IF(C5>0,"TİCARİ BİLANÇO KARI","TİCARİ BİLANÇO ZARARI")) | C5: ='GELİR TABLOSU'!C85 | D5: ='GELİR TABLOSU'!E85 | E5: ='GELİR TABLOSU'!E85
B7: İLAVELER | C7: =C8+C9 | D7: =D8+D9 | E7: =E8+E9
B8: Kanunen Kabul Edilmeyen Giderler | D8: 2121363.7 | E8: =D8
B9: Finansman Gider Kısıtlaması | D9: ='KKEG FİN. KISITLAMA HESAPL'!E20 | E9: =D9
B11: ZARAR OLSA DAHİ İNDİRİLECEK İSTİSNA VE İNDİRİMLER | C11: =SUM(C12:C24) | D11: =SUM(D12:D24) | E11: =SUM(E12:E24)
B12: İştirak Kazançları İstisnası
B13: Yurtdışı İştirak Kazançları
B14: Tam Mükellef Anonim Şirketlerin Yurtdışı İştirak Hisseleri Satış Kazançları
B15: Emisyon Primi Kazancı | E15: =D15
B16: Taşınmaz Satış Kazancı İstisnası
B17: İştirak Hissesi Satış Kazancı İstisnası
B18: Yurt Dışı Şube Kazançları
B19: Yurt Dışı İnşaat Onarma, Montaj ve Teknik Hizmetlerden Sağlanan Kazançlar
B20: Serbest Bölgelerde Elde Edilen Kazançlar | E20: =D20
B21: Teknoloji Geliştirme Bölgelerinde Elde Edilen Kazançlar | E21: 0
B22: Sinai Mülkiyet Haklarında İstisna
B23: Kur Korumalı Mevduat Geliri
B24: Diğer İndirimler ve İstisnalar
B26: KAZANCIN BULUNMASI HALİNDE İNDİRİLECEK İSTİSNA VE İNDİRİMLER | C26: =SUM(C27:C36) | D26: =SUM(D27:D36) | E26: =SUM(E27:E36)
B27: Ar-Ge İndirimi | E27: =D27
B28: Tasarım İndirimi | E28: =D28
B29: Sponsorluk Harcamaları
B30: Bağış ve Yardımlar
B31: Risturnlar | E31: =D31
B32: Yatırım İndirimi İstisnası
B33: Nakdi Sermaye Artışından Kaynaklanan Faiz İndirimi
B34: Teknogirişim Sermaye Desteği İndirimi
B35: Teknokent Sermaye Desteği İndirimi
B36: Diğer İndirimler
B38: MALİ KAR | C38: =C5+C7-C11-C26 | D38: =D5+D7-D11-D26 | E38: =E5+E7-E11-E26
B40: MAHSUP EDİLECEK GEÇMİŞ YIL ZARARLARI | E40: =D40
B42: GEÇİCİ VERGİ MATRAHI | C42: =IF((C38-C40)<0,0,(C38-C40)) | D42: =D38-D40 | E42: =E38-E40 | F42: ÖDENMESİ GEREKEN VERGİ
B44: HESAPLANAN GEÇİCİ VERGİ | C44: =C42*0.22 | D44: =D42*0.25 | E44: =E42*0.1 | F44: =MAX(D44:E44)
B46: ÖNCEKİ DÖNEMLERDE HESAPLANAN GEÇİCİ VERGİ | C46: 0 | D46: 4491166.7 | E46: =D46 | F46: =E46
B48: ÖDENMESİ GEREKEN GEÇİCİ VERGİ | C48: =C44-C46 | D48: =+D44-D46 | E48: =E44-E46 | F48: =F44-F46
B50: MAHSUP EDİLECEK YABANCI ÜLKELERDE ÖDENEN VERGİ TUTARI | C50: 0 | D50: 0 | E50: =D50 | F50: =E50
B52: MAHSUP EDİLECEK TEVKİFAT TUTARI | C52: 0 | D52: 0 | E52: =D52 | F52: =E52
B54: ÖDENECEK GEÇİCİ VERGİ | C54: =IF((C48-C50-C52)<0,0,(C48-C50-C52)) | D54: =IF((D48-D50-D52)<0,0,(D48-D50-D52)) | E54: =IF((E48-E50-E52)<0,0,(E48-E50-E52)) | F54: =IF((F48-F50-F52)<0,0,(F48-F50-F52))
...

Sheet BİLANÇO
A1: ANASAYFA | I1: SYF.3
B3: ='ANA SAYFA'!F11
B4: KARŞILAŞTIRMALI AYRINTILI BİLANÇO
D7: ='GELİR TABLOSU'!C6 | E7: ='GELİR TABLOSU'!E6 | H7: =D7 | I7: =E7
B8: 1 | C8: DÖNEN VARLIKLAR | D8: =SUM(D9+D15+D22+D32+D41+D49+D53+D56) | E8: =SUM(E9+E15+E22+E32+E41+E49+E53+E56) | F8: 3 | G8: KISA VADELİ YABANCI KAYNAKLAR | H8: =SUM(H10+H21+H27+H34+H37+H40+H46+H54+H58) | I8: =SUM(I10+I21+I27+I34+I37+I40+I46+I54+I58)
B9: 10 | C9: Hazır Değerler | D9: =SUM(D10,D11,D12,-D13,D14) | E9: =SUM(E10,E11,E12,-E13,E14)
B10: 100 | C10: Kasa | D10: 55000 | E10: 55000 | F10: 30 | G10: Mali Borçlar | H10: =SUM(H11,H12,-H13,H14,H15,H16,H17,H18,-H19,H20) | I10: =SUM(I11,I12,-I13,I14,I15,I16,I17,I18,-I19,I20)
B11: 101 | C11: Alınan Çekler | F11: 300 | G11: Banka Kredileri | H11: 2300000 | I11: 2300000
B12: 102 | C12: Bankalar | D12: 450000 | E12: 450000 | F12: 301 | G12: Finansal Kir.İşlemlerinden Doğan Borçlar
B13: 103 | C13: Verilen Çekler ve Ödeme Emir.(-) | D13: 280000 | E13: 280000 | F13: 302 | G13: Ertelenmiş Fin.Kir.Borçlanma Mal. (-)
B14: 108 | C14: Diğer Hazır Değerler | F14: 303 | G14: Uzun Vadeli Kredilerin
B15: 11 | C15: Menkul Kıymetler | D15: =SUM(D16,D17,D18,D19,-D20,-D21) | E15: =SUM(E16,E17,E18,E19,-E20,-E21) | G15: Anapara Taksitleri ve Faizleri
B16: 110 | C16: Hisse Senetleri | F16: 304 | G16: Tahvil, Anapara, Borç Taksit ve Faizleri
B17: 111 | C17: Özel Kesim Tahv. Senet ve Bon. | F17: 305 | G17: Çıkarılmış Bonolar ve Senetler
B18: 112 | C18: Kamu Kesimi Tahv. Senet ve Bon. | F18: 306 | G18: Çıkarılmış, Diğer Menkul Kıymetler
B19: 118 | C19: Diğer Menkul Kıymetler | F19: 308 | G19: Menkul Kıymetler İhraç Farkları (-)
B20: 119 | C20: Menkul Kıymetler Değer | F20: 309 | G20: Diğer Mali Borçlar
C21: Düşüklüğü Karşılığı (-) | F21: 32 | G21: Ticari Borçlar | H21: =SUM(H22,H23,-H24,H25,H26) | I21: =SUM(I22,I23,-I24,I25,I26)
B22: 12 | C22: Ticari Alacaklar | D22: =SUM(D23,D24,-D25,-D26,-D27,D28,D29,D30,-D31) | E22: =SUM(E23,E24,-E25,-E26,-E27,E28,E29,E30,-E31) | F22: 320 | G22: Satıcılar | H22: 2200000 | I22: 2200000
B23: 120 | C23: Alıcılar | D23: 3700000 | E23: 3700000 | F23: 321 | G23: Borç Senetleri | H23: 450000 | I23: 450000
B24: 121 | C24: Alacak Senetleri | D24: 350000 | E24: 350000 | F24: 322 | G24: Borç Senetleri Reeskontu (-)
B25: 122 | C25: Alacak Senetleri Reeskontu (-) | F25: 326 | G25: Alınan Depozito ve Teminatlar
B26: 124 | C26: Kazanılmamış Finansal Kiralama | F26: 329 | G26: Diğer Ticari Borçlar
C27: Faiz Gelirleri (-) | F27: 33 | G27: Diğer Borçlar | H27: =SUM(H28,H29,H30,H31,H32,-H33) | I27: =SUM(I28,I29,I30,I31,I32,-I33)
B28: 126 | C28: Verilen Depozito ve Teminatlar | D28: 45000 | E28: 45000 | F28: 331 | G28: Ortaklara Borçlar
B29: 127 | C29: Diğer Ticari Alacaklar | F29: 332 | G29: İştiraklere Borçlar
B30: 128 | C30: Şüpheli Ticari Alacaklar | D30: 320000 | E30: 320000 | F30: 333 | G30: Bağlı Ortaklıklara Borçlar
B31: 129 | C31: Şüpheli Ticari Alacaklar Karş. (-) | D31: 320000 | E31: 320000 | F31: 335 | G31: Personele Borçlar | H31: 40000 | I31: 40000
B32: 13 | C32: Diğer Alacaklar | D32: =SUM(D33,D34,D35,D36,D37,-D38,D39,-D40) | E32: =SUM(E33,E34,E35,E36,E37,-E38,E39,-E40) | F32: 336 | G32: Diğer Çeşitli Borçlar
B33: 131 | C33: Ortaklardan Alacaklar | D33: 50000 | E33: 50000 | F33: 337 | G33: Diğer Borç Senetleri Reeskontu (-)
B34: 132 | C34: İştiraklerden Alacaklar | F34: 34 | G34: Alınan Avanslar | H34: =SUM(H35:H36) | I34: =SUM(I35:I36)
B35: 133 | C35: Bağlı Ortaklıklardan Alacaklar | F35: 340 | G35: Alınan Sipariş Avansları
B36: 135 | C36: Personelden Alacaklar | F36: 349 | G36: Alınan Diğer Avanslar
B37: 136 | C37: Diğer Çeşitli Alacaklar | F37: 35 | G37: Yıllara Yaygın İnş. Ve On. Hak. | H37: =SUM(H38:H39) | I37: =SUM(I38:I39)
B38: 137 | C38: Diğer Alacak Senetleri Reesk. (-) | F38: 350 | G38: Yıllara Yaygın İnş. Ve On. Hak. bedelleri
B39: 138 | C39: Şüpheli Diğer Alacaklar | F39: 358 | G39: Yıllara Yaygın İnş. Enflasyon Düz. Hesabı
B40: 139 | C40: Şüpheli Diğer Alacaklar Karşılığı (-) | F40: 36 | G40: Ödenecek Vergi ve Diğer Yüküm. | H40: =SUM(H41:H45) | I40: =SUM(I41:I45)
B41: 15 | C41: Stoklar | D41: =SUM(D42,D43,D44,D45,D46,-D47,D48) | E41: =SUM(E42,E43,E44,E45,E46,-E47,E48) | F41: 360 | G41: Ödenecek Vergi ve Fonları | H41: 160000 | I41: 160000
B42: 150 | C42: İlk Madde ve Malzeme | D42: 750000 | E42: 1800000 | F42: 361 | G42: Ödenecek Sosyal Güvenlik Kesintileri | H42: 70000 | I42: 70000
B43: 151 | C43: Yarı Mamüller | D43: 200000 | E43: 7700000 | F43: 368 | G43: Vadesi Geçmiş Ert. veya Taksitlendirilmiş
...

Sheet BİLANÇO ANALİZİ
A1: ANASAYFA | G1: SYF.4
B3: ='ANA SAYFA'!F11
B4: BİLANÇO DİKEY ANALİZİ
D6: ='GELİR TABLOSU'!C6 | E6: % | F6: ='GELİR TABLOSU'!E6 | G6: %
B7: 1 | C7: DÖNEN VARLIKLAR | D7: =SUM(D8+D9+D10+D11+D12+D13+D14+D15) | E7: =D7/D30*100 | F7: =SUM(F8+F9+F10+F11+F12+F13+F14+F15) | G7: =F7/F30*100
B8: 10 | C8: Hazır Değerler | D8: =BİLANÇO!D9 | E8: =D8/D30*100 | F8: =BİLANÇO!E9 | G8: =F8/F30*100
B9: 11 | C9: Menkul Kıymetler | D9: =BİLANÇO!D15 | E9: =D9/D30*100 | F9: =BİLANÇO!E15 | G9: =F9/F30*100
B10: 12 | C10: Ticari Alacaklar | D10: =BİLANÇO!D22 | E10: =D10/D30*100 | F10: =BİLANÇO!E22 | G10: =F10/F30*100
B11: 13 | C11: Diğer Alacaklar | D11: =BİLANÇO!D32 | E11: =D11/D30*100 | F11: =BİLANÇO!E32 | G11: =F11/F30*100
B12: 15 | C12: Stoklar | D12: =BİLANÇO!D41 | E12: =D12/D30*100 | F12: =BİLANÇO!E41 | G12: =F12/F30*100
B13: 17 | C13: Yıllara Yaygın İnş. Ve On. Mal. | D13: =BİLANÇO!D49 | E13: =D13/D30*100 | F13: =BİLANÇO!E49 | G13: =F13/F30*100
B14: 18 | C14: Gel. Ayl. Ait Gid. Ve Gelir Tah. | D14: =BİLANÇO!D53 | E14: =D14/D30*100 | F14: =BİLANÇO!E53 | G14: =F14/F30*100
B15: 19 | C15: Diğer Dönen Varlıklar | D15: =BİLANÇO!D56 | E15: =D15/D30*100 | F15: =BİLANÇO!E56 | G15: =F15/F30*100
B16: 2 | C16: DURAN VARLIKLAR | D16: =SUM(D17+D18+D19+D20+D21+D22+D23+D24) | E16: =D16/D30*100 | F16: =SUM(F17+F18+F19+F20+F21+F22+F23+F24) | G16: =F16/F30*100
B17: 22 | C17: Ticari Alacaklar | D17: =BİLANÇO!D67 | E17: =D17/D30*100 | F17: =BİLANÇO!E67 | G17: =F17/F30*100
B18: 23 | C18: Diğer Alacaklar | D18: =BİLANÇO!D74 | E18: =D18/D30*100 | F18: =BİLANÇO!E74 | G18: =F18/F30*100
B19: 24 | C19: Mali Duran Varlıklar | D19: =BİLANÇO!D82 | E19: =D19/D30*100 | F19: =BİLANÇO!E82 | G19: =F19/F30*100
B20: 25 | C20: Maddi Duran Varlıklar | D20: =BİLANÇO!D96 | E20: =D20/D30*100 | F20: =BİLANÇO!E96 | G20: =F20/F30*100
B21: 26 | C21: Maddi Olmayan Duran Varlıklar | D21: =BİLANÇO!D107 | E21: =D21/D30*100 | F21: =BİLANÇO!E107 | G21: =F21/F30*100
B22: 27 | C22: Özel Tükenmeye Tabi Varlıklar | D22: =BİLANÇO!D116 | E22: =D22/D30*100 | F22: =BİLANÇO!E116 | G22: =F22/F30*100
B23: 28 | C23: Gelecek Yıllara Ait Giderler ve Gelir Tahakukları | D23: =BİLANÇO!D122 | E23: =D23/D30*100 | F23: =BİLANÇO!E122 | G23: =F23/F30*100
B24: 29 | C24: Diğer Duran Varlıklar | D24: =BİLANÇO!D126 | E24: =D24/D30*100 | F24: =BİLANÇO!E126 | G24: =F24/F30*100
C26: DÖNEN VARLIKLAR TOPLAMI | D26: =D7 | E26: =D26/D30*100 | F26: =F7 | G26: =F26/F30*100
C28: DURAN VARLIKLAR TOPLAMI | D28: =D16 | E28: =D28/D30*100 | F28: =F16 | G28: =F28/F30*100
C30: AKTİF (VARLIKLAR) TOPLAMI | D30: =D26+D28 | E30: =E26+E28 | F30: =F26+F28 | G30: =G26+G28
D32: ='GELİR TABLOSU'!C6 | E32: % | F32: ='GELİR TABLOSU'!E6 | G32: %
B33: 3 | C33: KISA VADELİ YABANCI KAYNAKLAR | D33: =SUM(D35+D36+D37+D38+D39+D40+D41+D42+D43) | E33: =D33/D65*100 | F33: =SUM(F35+F36+F37+F38+F39+F40+F41+F42+F43) | G33: =F33/F65*100
B35: 30 | C35: Mali Borçlar | D35: =BİLANÇO!H10 | E35: =D35/D65*100 | F35: =BİLANÇO!I10 | G35: =F35/F65*100
B36: 32 | C36: Ticari Borçlar | D36: =BİLANÇO!H21 | E36: =D36/D65*100 | F36: =BİLANÇO!I21 | G36: =F36/F65*100
B37: 33 | C37: Diğer Borçlar | D37: =BİLANÇO!H27 | E37: =D37/D65*100 | F37: =BİLANÇO!I27 | G37: =F37/F65*100
B38: 34 | C38: Alınan Avanslar | D38: =BİLANÇO!H34 | E38: =D38/D65*100 | F38: =BİLANÇO!I34 | G38: =F38/F65*100
B39: 35 | C39: Yıllara Yaygın İnş. Ve On. Hak. | D39: =BİLANÇO!H37 | E39: =D39/D65*100 | F39: =BİLANÇO!I37 | G39: =F39/F65*100
B40: 36 | C40: Ödenecek Vergi ve Diğer Yüküm. | D40: =BİLANÇO!H40 | E40: =D40/D65*100 | F40: =BİLANÇO!I40 | G40: =F40/F65*100
B41: 37 | C41: Borç ve Gider Karşılıkları | D41: =BİLANÇO!H46 | E41: =D41/D65*100 | F41: =BİLANÇO!I46 | G41: =F41/F65*100
B42: 38 | C42: Gelecek Aylara Ait Gelirler ve Gider Tahakkukları | D42: =BİLANÇO!H54 | E42: =D42/D65*100 | F42: =BİLANÇO!I54 | G42: =F42/F65*100
B43: 39 | C43: Diğer Kısa Vadeli Yabancı Kaynaklar | D43: =BİLANÇO!H58 | E43: =D43/D65*100 | F43: =BİLANÇO!I58 | G43: =F43/F65*100
B45: 4 | C45: UZUN VADELİ YABANCI KAYNAKLAR | D45: =SUM(D46+D47+D48+D49+D50+D51+D52) | E45: =D45/D65*100 | F45: =SUM(F46+F47+F48+F49+F50+F51+F52) | G45: =F45/F65*100
B46: 40 | C46: Mali Borçlar | D46: =BİLANÇO!H67 | E46: =D46/D65*100 | F46: =BİLANÇO!I67 | G46: =F46/F65*100
B47: 42 | C47: Ticari Borçlar | D47: =BİLANÇO!H76 | E47: =D47/D65*100 | F47: =BİLANÇO!I76 | G47: =F47/F65*100
B48: 43 | C48: Diğer Borçlar | D48: =BİLANÇO!H82 | E48: =D48/D65*100 | F48: =BİLANÇO!I82 | G48: =F48/F65*100
...

Sheet ORAN ANALİZİ
A1: ANASAYFA | G1: SYF.5
B3: ='ANA SAYFA'!F11
B5: LİKİDİTE ORANLARI | D5: =BİLANÇO!D7 | E5: =BİLANÇO!E7 | F5: İDEALİ | G5: DURUM
B7: Cari Oran | C7: Dönen Varlıklar | D7: ='BİLANÇO ANALİZİ'!D7/'BİLANÇO ANALİZİ'!D33 | E7: ='BİLANÇO ANALİZİ'!F7/'BİLANÇO ANALİZİ'!F33 | F7: 1 | G7: =IF(E7<F7,"DİKKAT","İYİ")
C8: Kısa Vadeli Yabancı Kaynaklar
B9: Likidite Oranı | C9: Dönen Varlıklar - Stoklar | D9: =('BİLANÇO ANALİZİ'!D7-'BİLANÇO ANALİZİ'!D12)/'BİLANÇO ANALİZİ'!D33 | E9: =('BİLANÇO ANALİZİ'!F7-'BİLANÇO ANALİZİ'!F12)/'BİLANÇO ANALİZİ'!F33 | F9: 0.75 | G9: =IF(E9<F9,"DİKKAT","İYİ")
C10: Kısa Vadeli Yabancı kaynaklar
B11: Nakit Oranı | C11: Hazır Değerler + Menkul Kıymetler | D11: =('BİLANÇO ANALİZİ'!D8+'BİLANÇO ANALİZİ'!D9)/'BİLANÇO ANALİZİ'!D33 | E11: =('BİLANÇO ANALİZİ'!F8+'BİLANÇO ANALİZİ'!F9)/'BİLANÇO ANALİZİ'!F33 | F11: 0.25 | G11: =IF(E11<F11,"DİKKAT","İYİ")
C12: Kısa Vadeli Yabancı Kaynaklar
B13: Net Nakit Oran | C13: Hazır Değerler + Menkul Kıymetler-Alınan Çekler | D13: =('BİLANÇO ANALİZİ'!D8+'BİLANÇO ANALİZİ'!D9-BİLANÇO!D11)/('BİLANÇO ANALİZİ'!D33-BİLANÇO!H28-BİLANÇO!H35) | E13: =('BİLANÇO ANALİZİ'!F8+'BİLANÇO ANALİZİ'!F9-BİLANÇO!#REF!)/('BİLANÇO ANALİZİ'!F33-BİLANÇO!I28-BİLANÇO!I35) | F13: 0.2 | G13: =IF(E13<F13,"DİKKAT","İYİ")
C14: Kısa Vd.Yab.Kayn.-Ortaklara Borç.-Alınan Sip.Avansları
B15: Çalışma Sermayesi | C15: Dönen Varlıklar - Kısa Vadeli Yabancı Kaynak | D15: ='BİLANÇO ANALİZİ'!D7-'BİLANÇO ANALİZİ'!D33 | E15: ='BİLANÇO ANALİZİ'!F7-'BİLANÇO ANALİZİ'!F33 | G15: =IF(E15<F15,"DİKKAT","İYİ")
B17: Net Çalışma Sermayesi | C17: (Dönen Varlıklar-Stoklar)- Kısa Vd Yabancı Kaynak | D17: ='BİLANÇO ANALİZİ'!D7-'BİLANÇO ANALİZİ'!D12-'BİLANÇO ANALİZİ'!D33 | E17: ='BİLANÇO ANALİZİ'!F7-'BİLANÇO ANALİZİ'!F12-'BİLANÇO ANALİZİ'!F33 | F17: =+F15/2 | G17: =IF(E17<F17,"DİKKAT","İYİ")
B19: SERMAYE YAPISI ORANLARI | D19: =D5 | E19: =E5 | F19: İDEALİ | G19: DURUM
B21: Yabancı Kaynak Oranı (%) | C21: Toplam Yabancı Kaynaklar | D21: ='BİLANÇO ANALİZİ'!D61/'BİLANÇO ANALİZİ'!D65 | E21: ='BİLANÇO ANALİZİ'!F61/'BİLANÇO ANALİZİ'!F65 | F21: 0.5
C22: Pasif Toplamı
B23: Öz Kaynak Oranı (%) | C23: Öz Kaynaklar | D23: ='BİLANÇO ANALİZİ'!D63/'BİLANÇO ANALİZİ'!D65 | E23: ='BİLANÇO ANALİZİ'!F63/'BİLANÇO ANALİZİ'!F65 | F23: 0.5
C24: Pasif Toplamı
B26: KARLILIK ORANLARI | D26: =D5 | E26: =E5 | F26: İDEALİ | G26: DURUM
B28: Brüt Kar Marjı | C28: Brüt Satış Karı | D28: ='GELİR TABLOSU'!C27/'GELİR TABLOSU'!C19 | E28: ='GELİR TABLOSU'!E27/'GELİR TABLOSU'!E19
C29: Net Satışlar
B30: Net Kar Marjı | C30: Vergi Sonrası Kar | D30: ='GELİR TABLOSU'!C85/'GELİR TABLOSU'!C19 | E30: ='GELİR TABLOSU'!E85/'GELİR TABLOSU'!E19
C31: Net Satışlar
B32: Aktif (Yatırım) Karlılık Oranı | C32: Vergi Sonrası Kar | D32: ='GELİR TABLOSU'!C85/BİLANÇO!D140 | E32: ='GELİR TABLOSU'!E85/BİLANÇO!E140
C33: Aktif Toplamı
B34: Satışların Maliyeti Oranı | C34: Satışların Maliyeti | D34: ='GELİR TABLOSU'!C20/'GELİR TABLOSU'!C19 | E34: ='GELİR TABLOSU'!E20/'GELİR TABLOSU'!E19
C35: Net satışlar

Sheet KKEG FİN. KISITLAMA HESAPL
D5: ='GELİR TABLOSU'!C6 | E5: ='GELİR TABLOSU'!E6 | G5: Not: Yabancı Kaynaklara ait, Kambiyo Zararlarının tespiti için; hem 646 hem de 656 hesapta "Yabancı kaynaklara ait Kambiyo karı/zararı" isimli alt hesap açmak gerekecektir. Bu doğrultuda dönem sonlarında Yabancı Kaynaklara ait bu 2 hesabın karşılaştırılarak toplamda kambiyo zararı çıkıyor ise tabloya yazmak gerekir.
C6: YABANCI KAYNAKLAR TOPLAMI | D6: =BİLANÇO!H8+BİLANÇO!H66 | E6: =BİLANÇO!I8+BİLANÇO!I66
C7: ÖZ KAYNAKLAR | D7: =BİLANÇO!H106 | E7: =BİLANÇO!I106
C8: FARK | D8: =D6-D7 | E8: =E6-E7
B11: YABANCI KAYNAKLARA AİT | C11: 1- Kısa Vadeli Borçlanma Giderleri | D11: ='GELİR TABLOSU'!C64 | E11: ='GELİR TABLOSU'!E64 | G11: Kullanılan yabancı kaynakları Öz Kaynaklarını aşan işletmelerde, aşan kısma münhasır olmak üzere, yatırımın maliyetine eklenenler hariç, işletmelerde kullanılan yabancı kaynaklara ilişkin faiz, komisyon, vade farkı, kar payı, kur farkı ve benzeri adlar altında yapılan gider ve maliyet unsurları toplamının %10'u gider olarak kabul edilemeyecektir. (GVK 41.Md., KVK 11. Md.)
C12: 2- Uzun Vadeli Borçlanma Giderleri | D12: ='GELİR TABLOSU'!C65 | E12: ='GELİR TABLOSU'!E65
C13: 3- Komisyon Giderleri | D13: ='GELİR TABLOSU'!C53 | E13: ='GELİR TABLOSU'!E53
C14: 4- Kambiyo Zararları (Kur Farkı Geliri var ise düşülmeli) | D14: =IF(('GELİR TABLOSU'!C57-'GELİR TABLOSU'!C46)<0,0,('GELİR TABLOSU'!C57-'GELİR TABLOSU'!C46)) | E14: =IF(('GELİR TABLOSU'!E57-'GELİR TABLOSU'!E46)<0,0,('GELİR TABLOSU'!E57-'GELİR TABLOSU'!E46))
C15: TOPLAM | D15: =SUM(D11:D14) | E15: =SUM(E11:E14)
C18: Aşan Kısma Tekabül Eden Gider Toplamı | D18: =D15/D6*D8 | E18: =E15/E6*E8
C20: KKEG Yapılacak %10 Luk Kısım | D20: =IF(D18<0,0,D18*0.1) | E20: =IF(E18<0,0,E18*0.1)

Sheet EBİTDA
A1: ANASAYFA | E1: SYF.6
B4: ='ORAN ANALİZİ'!B3:G3
D6: ='ORAN ANALİZİ'!D5 | E6: ='ORAN ANALİZİ'!E5
C7: A- EBİT ( FVÖK ) | D7: =D9+D10 | E7: =E9+E10
C9: 1- Faiz | D9: ='GELİR TABLOSU'!C64 | E9: ='GELİR TABLOSU'!E64
C10: 2- Vergi Öncesi Kar | D10: ='GELİR TABLOSU'!C80 | E10: ='GELİR TABLOSU'!E80
C12: B- AMORTİSMAN | D12: =D14 | E12: =E14
C14: 1- Amortisman
C16: C- EBİTDA ( FVAÖK )* | D16: =D12+D7 | E16: =E12+E7
C17: D- FVAÖK ORANI | D17: =D16/'GELİR TABLOSU'!C19 | E17: =E16/'GELİR TABLOSU'!E19
C18: E- SEKTÖR ÇARPANI** | D18: =D20 | E18: =E20
C20: 1- Katsayı | D20: 8 | E20: 8
C22: FİRMA DEĞERİ | D22: =D16*D18 | E22: =E16*E18
C24: F- NET DEBTS ( NET FİNANSAL BORÇLAR ) | D24: =D26-D27 | E24: =E26-E27
C26: 1- Finansal Borçlar | D26: =BİLANÇO!H10+BİLANÇO!H67 | E26: =BİLANÇO!I10+BİLANÇO!I67
C27: 2- Nakit ve Nakit Benzerleri | D27: =BİLANÇO!D9 | E27: =BİLANÇO!E9
C28: G- NET DEBTS / EBİTDA | D28: =D24/D16 | E28: =E24/E16
C29: H- EBİT / FİNANSMAN GİDERLERİ | D29: =D7/D9 | E29: =E7/E9
B34: *Faiz vergi amortisman öncesi kar
B35: ** Ebitdayı piyasa değerine getiren çarpan.

Sheet BORCA BATIKLIK
A1: ANASAYFA | E1: SYF.7
B3: SERMAYE KAYBI VE BORCA BATIKLIK TESPİTİ
C4: =EBİTDA!D6 | D4: =EBİTDA!E6
B5: ÖZKAYNAKLAR | C5: =C6+C11+C12+C14+C15+C16 | D5: =D6+D11+D12+D14+D15+D16
B6: Ödenmiş Sermaye | C6: =SUM(C7:C10) | D6: =SUM(D7:D10)
B7: Sermaye | C7: =BİLANÇO!H108 | D7: =BİLANÇO!I108
B8: Ödenmemiş Sermaye (-) | C8: =BİLANÇO!H109 | D8: =BİLANÇO!I109
B9: Sermaye Düzeltmesi Olumlu Farkları | C9: =BİLANÇO!H110 | D9: =BİLANÇO!I110
B10: Sermaye Düzeltmesi Olumsuz Farkları (-) | C10: =BİLANÇO!H111 | D10: =BİLANÇO!I111
B11: Sermaye Yedekleri | C11: =BİLANÇO!H112 | D11: =BİLANÇO!I112
B12: Kar Yedekleri | C12: =BİLANÇO!H119 | D12: =BİLANÇO!I119
B13: Yasal Yedekler | C13: =BİLANÇO!H120 | D13: =BİLANÇO!I120
B14: Geçmiş Yıllar Karları | C14: =BİLANÇO!H125 | D14: =BİLANÇO!I125
B15: Geçmiş Yıllar Zararları (-) | C15: =-BİLANÇO!H127 | D15: =-BİLANÇO!I127
B16: Dönem Net Karı (Zararı) | C16: =BİLANÇO!H129 | D16: =BİLANÇO!I129
A19: A | B19: Sermaye Kaybı Tutarının Tespiti = | C19: =C6+C13-C5 | D19: =D6+D13-D5 | E19: * | F19: A Değeri (-) ise borca batıklıktan söz edilemez
A20: B | B20: 1/2 Sermaye Kaybı Tespitine Esas Tutar= | C20: =(C6+C13)/2 | D20: =(D6+D13)/2 | E20: ** | F20: B, A 'dan büyükse borca batıklıktan söz edilemez
A21: C | B21: 2/3 Sermaye Kaybı Tespitine Esas Tutar= | C21: =(C6+C13)/3*2 | D21: =(D6+D13)/3*2 | E21: *** | F21: C, A 'dan büyükse borca batıklıktan söz edilemez

Sheet KİK ORANLARI
B1: ANASAYFA | D1: SYF.8
B3: KİK ORANLARI
B5: Yıl / Yıllar | C5: ='BİLANÇO ANALİZİ'!D6 | D5: ='BİLANÇO ANALİZİ'!F6
B6: Dönen Varlıklar | C6: ='BİLANÇO ANALİZİ'!D7 | D6: ='BİLANÇO ANALİZİ'!F7
B7: Kısa Vadeli Borçlar | C7: ='BİLANÇO ANALİZİ'!D33 | D7: ='BİLANÇO ANALİZİ'!F33
B8: Öz Kaynaklar | C8: ='BİLANÇO ANALİZİ'!D53 | D8: ='BİLANÇO ANALİZİ'!F53
B9: Toplam Aktif | C9: ='BİLANÇO ANALİZİ'!D30 | D9: ='BİLANÇO ANALİZİ'!F30
B10: Yıllara Yaygın İnşaat Maliyetleri (Varsa) | C10: =BİLANÇO!D49 | D10: =BİLANÇO!E49
B11: Kısa Vadeli Banka Borçları | C11: =BİLANÇO!H10 | D11: =BİLANÇO!I10
B12: Yıllara Yaygın İnşaat Hakediş Gelirleri (Varsa) | C12: =BİLANÇO!H37 | D12: =BİLANÇO!I37
B14: BİLANÇO ORANLARI
B15: Yıllar | C15: =C5 | D15: =D5 | E15: ORTALAMA | F15: YETERLİK KRİTERLERİ
B16: Cari Oran (Dönen Varlıklar/ Kısa Vadeli Borçlar) | C16: =(C6-C10)/(C7-C12) | D16: =(D6-D10)/(D7-D12) | E16: =((C6+D6)-(C10+D10))/((C7+D7)-(C12+D12)) | F16: En az 0,75 olması
B18: Öz Kaynak Oranı (Öz Kaynaklar/Toplam Aktif) | C18: =C8/(C9-C10) | D18: =D8/(D9-D10) | E18: =(C8+D8)/((C9+D9)-(C10+D10)) | F18: En az 0,15 olması
B20: Kısa Vadeli Banka Borçları/Öz Kaynaklar | C20: =C11/C8 | D20: =D11/D8 | E20: =(C11+D11)/(C8+D8) | F20: 0,50'den küçük olması
B23: Cari oran hesaplanırken yıllara yaygın inşaat maliyetleri dönen varlıklardan; yıllara yaygın inşaat hakediş gelirleri ise kısa vadeli borçlardan düşülecektir.
B24: Öz kaynak oranı hesaplanırken yıllara yaygın inşaat maliyetleri toplam aktiflerden düşülecektir.
B26: Ortalama değerlerin kullanılabilmesi için ihale yönetmeliğine bakılması gerekir. Mal ve hizmet alım ihalelelerinde son 2 yıl Yapım işi ihalelerinde son 3 yıl ortalaması kullanılabilir

Sheet ÖNCEKİ DÖNEM DETAY MİZAN

Sheet CARİ DÖNEM DETAY MİZAN
